Workbook

Sheet Resum
B1: Seguiment de cims · 100 Cims FEEC, tresmils i sostres
B2: Repte FEEC: calen 100 dels 150 «essencials» (des de l'1/7/2019); després compten tots els cims per als reptes 2×100, 3×100… Tresmils: llista UIAA de 212. Generat per l'app Cims.
B4: 100 Cims FEEC | C4: Essencials assolits | D4: ="Falten per als "&IF(C5<100,100,(INT(G5/100)+1)*100) | E4: Progrés del repte (centenes) | F4: No essencials assolits | G4: Total cims FEEC assolits | H4: % del total FEEC | I4: Punts
C5: =COUNTIFS('100 Cims FEEC'!$E$5:$E$526,"Essencial",'100 Cims FEEC'!$G$5:$G$526,"Sí") | D5: =IF(C5<100,100-C5,IF(C5<100,100,(INT(G5/100)+1)*100)-G5) | E5: =IF(C5<100,C5/100,G5/100) | F5: =COUNTIFS('100 Cims FEEC'!$E$5:$E$526,"No essencial",'100 Cims FEEC'!$G$5:$G$526,"Sí") | G5: =C5+F5 | H5: =G5/COUNTA('100 Cims FEEC'!$E$5:$E$526) | I5: =COUNTA('Els meus punts'!$B$5:$B$6)
B7: ="Progrés cap als "&IF(C5<100,100,(INT(G5/100)+1)*100) | C7: =REPT("█",ROUND((IF(C5<100,C5/100,MOD(G5,100)/100))*30,0))&REPT("░",30-ROUND((IF(C5<100,C5/100,MOD(G5,100)/100))*30,0))&" "&TEXT(IF(C5<100,C5/100,MOD(G5,100)/100),"0%")&IF(C5<100," ("&C5&" de 100 essencials)"," ("&MOD(G5,100)&" de 100 cap als "&IF(C5<100,100,(INT(G5/100)+1)*100)&")")
B8: Sobre el total FEEC (522) | C8: =REPT("█",ROUND((H5)*30,0))&REPT("░",30-ROUND((H5)*30,0))&" "&TEXT((H5),"0%")
B9: Detall | C9: =C5&" de "&COUNTIF('100 Cims FEEC'!$E$5:$E$526,"Essencial")&" essencials · "&G5&" de "&COUNTA('100 Cims FEEC'!$E$5:$E$526)&" cims de la llista"&IF(C5>=100," · repte dels 100 superat","")
B11: Tresmils i sostres | C11: UIAA principals assolits | D11: UIAA secundaris assolits | E11: Total 3000 UIAA assolits | F11: % dels 212 UIAA | G11: 3000 catalans assolits (de 13) | H11: % 3000 catalans | I11: Sostres comarcals (de 43)
C12: =COUNTIFS('3000 Pirineu'!$E$5:$E$219,"Principal",'3000 Pirineu'!$G$5:$G$219,"Sí") | D12: =COUNTIFS('3000 Pirineu'!$E$5:$E$219,"Secundari",'3000 Pirineu'!$G$5:$G$219,"Sí") | E12: =C12+D12 | F12: =E12/(COUNTIF('3000 Pirineu'!$E$5:$E$219,"Principal")+COUNTIF('3000 Pirineu'!$E$5:$E$219,"Secundari")) | G12: =COUNTIFS('3000 Pirineu català'!$G$5:$G$20,"Sí",'3000 Pirineu català'!$D$5:$D$20,"Vigent") | H12: =G12/COUNTIF('3000 Pirineu català'!$D$5:$D$20,"Vigent") | I12: =COUNTIF('Sostres comarcals'!$G$5:$G$47,"Sí")
B14: Progrés 3000 UIAA (212) | C14: =REPT("█",ROUND((F12)*30,0))&REPT("░",30-ROUND((F12)*30,0))&" "&TEXT((F12),"0%")
B15: Progrés 3000 catalans (13) | C15: =REPT("█",ROUND((H12)*30,0))&REPT("░",30-ROUND((H12)*30,0))&" "&TEXT((H12),"0%")
B16: Progrés sostres comarcals (43) | C16: =REPT("█",ROUND((I12/COUNTA('Sostres comarcals'!$A$5:$A$47))*30,0))&REPT("░",30-ROUND((I12/COUNTA('Sostres comarcals'!$A$5:$A$47))*30,0))&" "&TEXT((I12/COUNTA('Sostres comarcals'!$A$5:$A$47)),"0%")
B17: Detall | C17: =C12&" de "&COUNTIF('3000 Pirineu'!$E$5:$E$219,"Principal")&" principals · "&D12&" de "&COUNTIF('3000 Pirineu'!$E$5:$E$219,"Secundari")&" secundaris · "&G12&" de "&COUNTIF('3000 Pirineu català'!$D$5:$D$20,"Vigent")&" tresmils catalans · "&I12&" de "&COUNTA('Sostres comarcals'!$A$5:$A$47)&" sostres comarcals"
B18: Progrés 4000 Alps (128) | C18: =REPT("█",ROUND((COUNTIF('4000 Alps'!$G$5:$G$132,"Sí")/COUNTA('4000 Alps'!$B$5:$B$132))*30,0))&REPT("░",30-ROUND((COUNTIF('4000 Alps'!$G$5:$G$132,"Sí")/COUNTA('4000 Alps'!$B$5:$B$132))*30,0))&" "&TEXT((COUNTIF('4000 Alps'!$G$5:$G$132,"Sí")/COUNTA('4000 Alps'!$B$5:$B$132)),"0%")&" ("&COUNTIFS('4000 Alps'!$F$5:$F$132,"Principal",'4000 Alps'!$G$5:$G$132,"Sí")&" de 82 principals · "&COUNTIF('4000 Alps'!$G$5:$G$132,"Sí")&" de 128 en total)"
B20: Per comarca principal | K20: Punts per grup
B21: Comarca principal | C21: Cims a la llista | D21: Essencials | E21: Essencials assolits | F21: Essencials pendents | G21: No essencials assolits | H21: % essencials fets | K21: Grup | L21: Punts | M21: Cims FEEC | N21: 3000 UIAA
B22: Alt Camp | C22: =COUNTIF('100 Cims FEEC'!$C$5:$C$526,B22) | D22: =COUNTIFS('100 Cims FEEC'!$C$5:$C$526,B22,'100 Cims FEEC'!$E$5:$E$526,"Essencial") | E22: =COUNTIFS('100 Cims FEEC'!$C$5:$C$526,B22,'100 Cims FEEC'!$E$5:$E$526,"Essencial",'100 Cims FEEC'!$G$5:$G$526,"Sí") | F22: =D22-E22 | G22: =COUNTIFS('100 Cims FEEC'!$C$5:$C$526,B22,'100 Cims FEEC'!$E$5:$E$526,"No essencial",'100 Cims FEEC'!$G$5:$G$526,"Sí") | H22: =IF(D22=0,"-",E22/D22) | K22: Internacionals | L22: =COUNTIF('Els meus punts'!$A$5:$A$6,K22) | M22: =COUNTIFS('Els meus punts'!$A$5:$A$6,K22,'Els meus punts'!$F$5:$F$6,"<>") | N22: =COUNTIFS('Els meus punts'!$A$5:$A$6,K22,'Els meus punts'!$J$5:$J$6,"Principal")+COUNTIFS('Els meus punts'!$A$5:$A$6,K22,'Els meus punts'!$J$5:$J$6,"Secundari")
B23: Alt Empordà | C23: =COUNTIF('100 Cims FEEC'!$C$5:$C$526,B23) | D23: =COUNTIFS('100 Cims FEEC'!$C$5:$C$526,B23,'100 Cims FEEC'!$E$5:$E$526,"Essencial") | E23: =COUNTIFS('100 Cims FEEC'!$C$5:$C$526,B23,'100 Cims FEEC'!$E$5:$E$526,"Essencial",'100 Cims FEEC'!$G$5:$G$526,"Sí") | F23: =D23-E23 | G23: =COUNTIFS('100 Cims FEEC'!$C$5:$C$526,B23,'100 Cims FEEC'!$E$5:$E$526,"No essencial",'100 Cims FEEC'!$G$5:$G$526,"Sí") | H23: =IF(D23=0,"-",E23/D23) | K23: Asturias | L23: =COUNTIF('Els meus punts'!$A$5:$A$6,K23) | M23: =COUNTIFS('Els meus punts'!$A$5:$A$6,K23,'Els meus punts'!$F$5:$F$6,"<>") | N23: =COUNTIFS('Els meus punts'!$A$5:$A$6,K23,'Els meus punts'!$J$5:$J$6,"Principal")+COUNTIFS('Els meus punts'!$A$5:$A$6,K23,'Els meus punts'!$J$5:$J$6,"Secundari")
B24: Alt Penedès | C24: =COUNTIF('100 Cims FEEC'!$C$5:$C$526,B24) | D24: =COUNTIFS('100 Cims FEEC'!$C$5:$C$526,B24,'100 Cims FEEC'!$E$5:$E$526,"Essencial") | E24: =COUNTIFS('100 Cims FEEC'!$C$5:$C$526,B24,'100 Cims FEEC'!$E$5:$E$526,"Essencial",'100 Cims FEEC'!$G$5:$G$526,"Sí") | F24: =D24-E24 | G24: =COUNTIFS('100 Cims FEEC'!$C$5:$C$526,B24,'100 Cims FEEC'!$E$5:$E$526,"No essencial",'100 Cims FEEC'!$G$5:$G$526,"Sí") | H24: =IF(D24=0,"-",E24/D24) | K24: Galicia | L24: =COUNTIF('Els meus punts'!$A$5:$A$6,K24) | M24: =COUNTIFS('Els meus punts'!$A$5:$A$6,K24,'Els meus punts'!$F$5:$F$6,"<>") | N24: =COUNTIFS('Els meus punts'!$A$5:$A$6,K24,'Els meus punts'!$J$5:$J$6,"Principal")+COUNTIFS('Els meus punts'!$A$5:$A$6,K24,'Els meus punts'!$J$5:$J$6,"Secundari")
B25: Alt Urgell | C25: =COUNTIF('100 Cims FEEC'!$C$5:$C$526,B25) | D25: =COUNTIFS('100 Cims FEEC'!$C$5:$C$526,B25,'100 Cims FEEC'!$E$5:$E$526,"Essencial") | E25: =COUNTIFS('100 Cims FEEC'!$C$5:$C$526,B25,'100 Cims FEEC'!$E$5:$E$526,"Essencial",'100 Cims FEEC'!$G$5:$G$526,"Sí") | F25: =D25-E25 | G25: =COUNTIFS('100 Cims FEEC'!$C$5:$C$526,B25,'100 Cims FEEC'!$E$5:$E$526,"No essencial",'100 Cims FEEC'!$G$5:$G$526,"Sí") | H25: =IF(D25=0,"-",E25/D25) | K25: Cims | L25: =COUNTIF('Els meus punts'!$A$5:$A$6,K25) | M25: =COUNTIFS('Els meus punts'!$A$5:$A$6,K25,'Els meus punts'!$F$5:$F$6,"<>") | N25: =COUNTIFS('Els meus punts'!$A$5:$A$6,K25,'Els meus punts'!$J$5:$J$6,"Principal")+COUNTIFS('Els meus punts'!$A$5:$A$6,K25,'Els meus punts'!$J$5:$J$6,"Secundari")
B26: Alta Ribagorça | C26: =COUNTIF('100 Cims FEEC'!$C$5:$C$526,B26) | D26: =COUNTIFS('100 Cims FEEC'!$C$5:$C$526,B26,'100 Cims FEEC'!$E$5:$E$526,"Essencial") | E26: =COUNTIFS('100 Cims FEEC'!$C$5:$C$526,B26,'100 Cims FEEC'!$E$5:$E$526,"Essencial",'100 Cims FEEC'!$G$5:$G$526,"Sí") | F26: =D26-E26 | G26: =COUNTIFS('100 Cims FEEC'!$C$5:$C$526,B26,'100 Cims FEEC'!$E$5:$E$526,"No essencial",'100 Cims FEEC'!$G$5:$G$526,"Sí") | H26: =IF(D26=0,"-",E26/D26) | K26: Escalades | L26: =COUNTIF('Els meus punts'!$A$5:$A$6,K26) | M26: =COUNTIFS('Els meus punts'!$A$5:$A$6,K26,'Els meus punts'!$F$5:$F$6,"<>") | N26: =COUNTIFS('Els meus punts'!$A$5:$A$6,K26,'Els meus punts'!$J$5:$J$6,"Principal")+COUNTIFS('Els meus punts'!$A$5:$A$6,K26,'Els meus punts'!$J$5:$J$6,"Secundari")
B27: Andorra | C27: =COUNTIF('100 Cims FEEC'!$C$5:$C$526,B27) | D27: =COUNTIFS('100 Cims FEEC'!$C$5:$C$526,B27,'100 Cims FEEC'!$E$5:$E$526,"Essencial") | E27: =COUNTIFS('100 Cims FEEC'!$C$5:$C$526,B27,'100 Cims FEEC'!$E$5:$E$526,"Essencial",'100 Cims FEEC'!$G$5:$G$526,"Sí") | F27: =D27-E27 | G27: =COUNTIFS('100 Cims FEEC'!$C$5:$C$526,B27,'100 Cims FEEC'!$E$5:$E$526,"No essencial",'100 Cims FEEC'!$G$5:$G$526,"Sí") | H27: =IF(D27=0,"-",E27/D27) | K27: Ferrades | L27: =COUNTIF('Els meus punts'!$A$5:$A$6,K27) | M27: =COUNTIFS('Els meus punts'!$A$5:$A$6,K27,'Els meus punts'!$F$5:$F$6,"<>") | N27: =COUNTIFS('Els meus punts'!$A$5:$A$6,K27,'Els meus punts'!$J$5:$J$6,"Principal")+COUNTIFS('Els meus punts'!$A$5:$A$6,K27,'Els meus punts'!$J$5:$J$6,"Secundari")
B28: Anoia | C28: =COUNTIF('100 Cims FEEC'!$C$5:$C$526,B28) | D28: =COUNTIFS('100 Cims FEEC'!$C$5:$C$526,B28,'100 Cims FEEC'!$E$5:$E$526,"Essencial") | E28: =COUNTIFS('100 Cims FEEC'!$C$5:$C$526,B28,'100 Cims FEEC'!$E$5:$E$526,"Essencial",'100 Cims FEEC'!$G$5:$G$526,"Sí") | F28: =D28-E28 | G28: =COUNTIFS('100 Cims FEEC'!$C$5:$C$526,B28,'100 Cims FEEC'!$E$5:$E$526,"No essencial",'100 Cims FEEC'!$G$5:$G$526,"Sí") | H28: =IF(D28=0,"-",E28/D28) | K28: Alpinisme | L28: =COUNTIF('Els meus punts'!$A$5:$A$6,K28) | M28: =COUNTIFS('Els meus punts'!$A$5:$A$6,K28,'Els meus punts'!$F$5:$F$6,"<>") | N28: =COUNTIFS('Els meus punts'!$A$5:$A$6,K28,'Els meus punts'!$J$5:$J$6,"Principal")+COUNTIFS('Els meus punts'!$A$5:$A$6,K28,'Els meus punts'!$J$5:$J$6,"Secundari")
B29: Bages | C29: =COUNTIF('100 Cims FEEC'!$C$5:$C$526,B29) | D29: =COUNTIFS('100 Cims FEEC'!$C$5:$C$526,B29,'100 Cims FEEC'!$E$5:$E$526,"Essencial") | E29: =COUNTIFS('100 Cims FEEC'!$C$5:$C$526,B29,'100 Cims FEEC'!$E$5:$E$526,"Essencial",'100 Cims FEEC'!$G$5:$G$526,"Sí") | F29: =D29-E29 | G29: =COUNTIFS('100 Cims FEEC'!$C$5:$C$526,B29,'100 Cims FEEC'!$E$5:$E$526,"No essencial",'100 Cims FEEC'!$G$5:$G$526,"Sí") | H29: =IF(D29=0,"-",E29/D29) | K29: Projectes | L29: =COUNTIF('Els meus punts'!$A$5:$A$6,K29) | M29: =COUNTIFS('Els meus punts'!$A$5:$A$6,K29,'Els meus punts'!$F$5:$F$6,"<>") | N29: =COUNTIFS('Els meus punts'!$A$5:$A$6,K29,'Els meus punts'!$J$5:$J$6,"Principal")+COUNTIFS('Els meus punts'!$A$5:$A$6,K29,'Els meus punts'!$J$5:$J$6,"Secundari")
B30: Baix Camp | C30: =COUNTIF('100 Cims FEEC'!$C$5:$C$526,B30) | D30: =COUNTIFS('100 Cims FEEC'!$C$5:$C$526,B30,'100 Cims FEEC'!$E$5:$E$526,"Essencial") | E30: =COUNTIFS('100 Cims FEEC'!$C$5:$C$526,B30,'100 Cims FEEC'!$E$5:$E$526,"Essencial",'100 Cims FEEC'!$G$5:$G$526,"Sí") | F30: =D30-E30 | G30: =COUNTIFS('100 Cims FEEC'!$C$5:$C$526,B30,'100 Cims FEEC'!$E$5:$E$526,"No essencial",'100 Cims FEEC'!$G$5:$G$526,"Sí") | H30: =IF(D30=0,"-",E30/D30) | K30: Total | L30: =SUM(L22:L29) | M30: =SUM(M22:M29) | N30: =SUM(N22:N29)
B31: Baix Ebre | C31: =COUNTIF('100 Cims FEEC'!$C$5:$C$526,B31) | D31: =COUNTIFS('100 Cims FEEC'!$C$5:$C$526,B31,'100 Cims FEEC'!$E$5:$E$526,"Essencial") | E31: =COUNTIFS('100 Cims FEEC'!$C$5:$C$526,B31,'100 Cims FEEC'!$E$5:$E$526,"Essencial",'100 Cims FEEC'!$G$5:$G$526,"Sí") | F31: =D31-E31 | G31: =COUNTIFS('100 Cims FEEC'!$C$5:$C$526,B31,'100 Cims FEEC'!$E$5:$E$526,"No essencial",'100 Cims FEEC'!$G$5:$G$526,"Sí") | H31: =IF(D31=0,"-",E31/D31)
B32: Baix Empordà | C32: =COUNTIF('100 Cims FEEC'!$C$5:$C$526,B32) | D32: =COUNTIFS('100 Cims FEEC'!$C$5:$C$526,B32,'100 Cims FEEC'!$E$5:$E$526,"Essencial") | E32: =COUNTIFS('100 Cims FEEC'!$C$5:$C$526,B32,'100 Cims FEEC'!$E$5:$E$526,"Essencial",'100 Cims FEEC'!$G$5:$G$526,"Sí") | F32: =D32-E32 | G32: =COUNTIFS('100 Cims FEEC'!$C$5:$C$526,B32,'100 Cims FEEC'!$E$5:$E$526,"No essencial",'100 Cims FEEC'!$G$5:$G$526,"Sí") | H32: =IF(D32=0,"-",E32/D32)
B33: Baix Llobregat | C33: =COUNTIF('100 Cims FEEC'!$C$5:$C$526,B33) | D33: =COUNTIFS('100 Cims FEEC'!$C$5:$C$526,B33,'100 Cims FEEC'!$E$5:$E$526,"Essencial") | E33: =COUNTIFS('100 Cims FEEC'!$C$5:$C$526,B33,'100 Cims FEEC'!$E$5:$E$526,"Essencial",'100 Cims FEEC'!$G$5:$G$526,"Sí") | F33: =D33-E33 | G33: =COUNTIFS('100 Cims FEEC'!$C$5:$C$526,B33,'100 Cims FEEC'!$E$5:$E$526,"No essencial",'100 Cims FEEC'!$G$5:$G$526,"Sí") | H33: =IF(D33=0,"-",E33/D33) | K33: 3000 UIAA per zona
B34: Baix Penedès | C34: =COUNTIF('100 Cims FEEC'!$C$5:$C$526,B34) | D34: =COUNTIFS('100 Cims FEEC'!$C$5:$C$526,B34,'100 Cims FEEC'!$E$5:$E$526,"Essencial") | E34: =COUNTIFS('100 Cims FEEC'!$C$5:$C$526,B34,'100 Cims FEEC'!$E$5:$E$526,"Essencial",'100 Cims FEEC'!$G$5:$G$526,"Sí") | F34: =D34-E34 | G34: =COUNTIFS('100 Cims FEEC'!$C$5:$C$526,B34,'100 Cims FEEC'!$E$5:$E$526,"No essencial",'100 Cims FEEC'!$G$5:$G$526,"Sí") | H34: =IF(D34=0,"-",E34/D34) | K34: Zona | L34: Principals | M34: Princ. fets | N34: Secundaris | O34: Sec. fets | P34: % total
B35: Barcelonès | C35: =COUNTIF('100 Cims FEEC'!$C$5:$C$526,B35) | D35: =COUNTIFS('100 Cims FEEC'!$C$5:$C$526,B35,'100 Cims FEEC'!$E$5:$E$526,"Essencial") | E35: =COUNTIFS('100 Cims FEEC'!$C$5:$C$526,B35,'100 Cims FEEC'!$E$5:$E$526,"Essencial",'100 Cims FEEC'!$G$5:$G$526,"Sí") | F35: =D35-E35 | G35: =COUNTIFS('100 Cims FEEC'!$C$5:$C$526,B35,'100 Cims FEEC'!$E$5:$E$526,"No essencial",'100 Cims FEEC'!$G$5:$G$526,"Sí") | H35: =IF(D35=0,"-",E35/D35) | K35: Z1 · Balaitús-Infiernos | L35: =COUNTIFS('3000 Pirineu'!$D$5:$D$219,K35,'3000 Pirineu'!$E$5:$E$219,"Principal") | M35: =COUNTIFS('3000 Pirineu'!$D$5:$D$219,K35,'3000 Pirineu'!$E$5:$E$219,"Principal",'3000 Pirineu'!$G$5:$G$219,"Sí") | N35: =COUNTIFS('3000 Pirineu'!$D$5:$D$219,K35,'3000 Pirineu'!$E$5:$E$219,"Secundari") | O35: =COUNTIFS('3000 Pirineu'!$D$5:$D$219,K35,'3000 Pirineu'!$E$5:$E$219,"Secundari",'3000 Pirineu'!$G$5:$G$219,"Sí") | P35: =IF(L35+N35=0,0,(M35+O35)/(L35+N35))
B36: Berguedà | C36: =COUNTIF('100 Cims FEEC'!$C$5:$C$526,B36) | D36: =COUNTIFS('100 Cims FEEC'!$C$5:$C$526,B36,'100 Cims FEEC'!$E$5:$E$526,"Essencial") | E36: =COUNTIFS('100 Cims FEEC'!$C$5:$C$526,B36,'100 Cims FEEC'!$E$5:$E$526,"Essencial",'100 Cims FEEC'!$G$5:$G$526,"Sí") | F36: =D36-E36 | G36: =COUNTIFS('100 Cims FEEC'!$C$5:$C$526,B36,'100 Cims FEEC'!$E$5:$E$526,"No essencial",'100 Cims FEEC'!$G$5:$G$526,"Sí") | H36: =IF(D36=0,"-",E36/D36) | K36: Z2 · Vignemale | L36: =COUNTIFS('3000 Pirineu'!$D$5:$D$219,K36,'3000 Pirineu'!$E$5:$E$219,"Principal") | M36: =COUNTIFS('3000 Pirineu'!$D$5:$D$219,K36,'3000 Pirineu'!$E$5:$E$219,"Principal",'3000 Pirineu'!$G$5:$G$219,"Sí") | N36: =COUNTIFS('3000 Pirineu'!$D$5:$D$219,K36,'3000 Pirineu'!$E$5:$E$219,"Secundari") | O36: =COUNTIFS('3000 Pirineu'!$D$5:$D$219,K36,'3000 Pirineu'!$E$5:$E$219,"Secundari",'3000 Pirineu'!$G$5:$G$219,"Sí") | P36: =IF(L36+N36=0,0,(M36+O36)/(L36+N36))
B37: Capcir | C37: =COUNTIF('100 Cims FEEC'!$C$5:$C$526,B37) | D37: =COUNTIFS('100 Cims FEEC'!$C$5:$C$526,B37,'100 Cims FEEC'!$E$5:$E$526,"Essencial") | E37: =COUNTIFS('100 Cims FEEC'!$C$5:$C$526,B37,'100 Cims FEEC'!$E$5:$E$526,"Essencial",'100 Cims FEEC'!$G$5:$G$526,"Sí") | F37: =D37-E37 | G37: =COUNTIFS('100 Cims FEEC'!$C$5:$C$526,B37,'100 Cims FEEC'!$E$5:$E$526,"No essencial",'100 Cims FEEC'!$G$5:$G$526,"Sí") | H37: =IF(D37=0,"-",E37/D37) | K37: Z3 · Monte Perdido | L37: =COUNTIFS('3000 Pirineu'!$D$5:$D$219,K37,'3000 Pirineu'!$E$5:$E$219,"Principal") | M37: =COUNTIFS('3000 Pirineu'!$D$5:$D$219,K37,'3000 Pirineu'!$E$5:$E$219,"Principal",'3000 Pirineu'!$G$5:$G$219,"Sí") | N37: =COUNTIFS('3000 Pirineu'!$D$5:$D$219,K37,'3000 Pirineu'!$E$5:$E$219,"Secundari") | O37: =COUNTIFS('3000 Pirineu'!$D$5:$D$219,K37,'3000 Pirineu'!$E$5:$E$219,"Secundari",'3000 Pirineu'!$G$5:$G$219,"Sí") | P37: =IF(L37+N37=0,0,(M37+O37)/(L37+N37))
B38: Cerdanya | C38: =COUNTIF('100 Cims FEEC'!$C$5:$C$526,B38) | D38: =COUNTIFS('100 Cims FEEC'!$C$5:$C$526,B38,'100 Cims FEEC'!$E$5:$E$526,"Essencial") | E38: =COUNTIFS('100 Cims FEEC'!$C$5:$C$526,B38,'100 Cims FEEC'!$E$5:$E$526,"Essencial",'100 Cims FEEC'!$G$5:$G$526,"Sí") | F38: =D38-E38 | G38: =COUNTIFS('100 Cims FEEC'!$C$5:$C$526,B38,'100 Cims FEEC'!$E$5:$E$526,"No essencial",'100 Cims FEEC'!$G$5:$G$526,"Sí") | H38: =IF(D38=0,"-",E38/D38) | K38: Z4 · La Munia | L38: =COUNTIFS('3000 Pirineu'!$D$5:$D$219,K38,'3000 Pirineu'!$E$5:$E$219,"Principal") | M38: =COUNTIFS('3000 Pirineu'!$D$5:$D$219,K38,'3000 Pirineu'!$E$5:$E$219,"Principal",'3000 Pirineu'!$G$5:$G$219,"Sí") | N38: =COUNTIFS('3000 Pirineu'!$D$5:$D$219,K38,'3000 Pirineu'!$E$5:$E$219,"Secundari") | O38: =COUNTIFS('3000 Pirineu'!$D$5:$D$219,K38,'3000 Pirineu'!$E$5:$E$219,"Secundari",'3000 Pirineu'!$G$5:$G$219,"Sí") | P38: =IF(L38+N38=0,0,(M38+O38)/(L38+N38))
B39: Cerdanya Nord | C39: =COUNTIF('100 Cims FEEC'!$C$5:$C$526,B39) | D39: =COUNTIFS('100 Cims FEEC'!$C$5:$C$526,B39,'100 Cims FEEC'!$E$5:$E$526,"Essencial") | E39: =COUNTIFS('100 Cims FEEC'!$C$5:$C$526,B39,'100 Cims FEEC'!$E$5:$E$526,"Essencial",'100 Cims FEEC'!$G$5:$G$526,"Sí") | F39: =D39-E39 | G39: =COUNTIFS('100 Cims FEEC'!$C$5:$C$526,B39,'100 Cims FEEC'!$E$5:$E$526,"No essencial",'100 Cims FEEC'!$G$5:$G$526,"Sí") | H39: =IF(D39=0,"-",E39/D39) | K39: Z5 · Néouvielle | L39: =COUNTIFS('3000 Pirineu'!$D$5:$D$219,K39,'3000 Pirineu'!$E$5:$E$219,"Principal") | M39: =COUNTIFS('3000 Pirineu'!$D$5:$D$219,K39,'3000 Pirineu'!$E$5:$E$219,"Principal",'3000 Pirineu'!$G$5:$G$219,"Sí") | N39: =COUNTIFS('3000 Pirineu'!$D$5:$D$219,K39,'3000 Pirineu'!$E$5:$E$219,"Secundari") | O39: =COUNTIFS('3000 Pirineu'!$D$5:$D$219,K39,'3000 Pirineu'!$E$5:$E$219,"Secundari",'3000 Pirineu'!$G$5:$G$219,"Sí") | P39: =IF(L39+N39=0,0,(M39+O39)/(L39+N39))
B40: Conca de Barberà | C40: =COUNTIF('100 Cims FEEC'!$C$5:$C$526,B40) | D40: =COUNTIFS('100 Cims FEEC'!$C$5:$C$526,B40,'100 Cims FEEC'!$E$5:$E$526,"Essencial") | E40: =COUNTIFS('100 Cims FEEC'!$C$5:$C$526,B40,'100 Cims FEEC'!$E$5:$E$526,"Essencial",'100 Cims FEEC'!$G$5:$G$526,"Sí") | F40: =D40-E40 | G40: =COUNTIFS('100 Cims FEEC'!$C$5:$C$526,B40,'100 Cims FEEC'!$E$5:$E$526,"No essencial",'100 Cims FEEC'!$G$5:$G$526,"Sí") | H40: =IF(D40=0,"-",E40/D40) | K40: Z6 · Bachimala | L40: =COUNTIFS('3000 Pirineu'!$D$5:$D$219,K40,'3000 Pirineu'!$E$5:$E$219,"Principal") | M40: =COUNTIFS('3000 Pirineu'!$D$5:$D$219,K40,'3000 Pirineu'!$E$5:$E$219,"Principal",'3000 Pirineu'!$G$5:$G$219,"Sí") | N40: =COUNTIFS('3000 Pirineu'!$D$5:$D$219,K40,'3000 Pirineu'!$E$5:$E$219,"Secundari") | O40: =COUNTIFS('3000 Pirineu'!$D$5:$D$219,K40,'3000 Pirineu'!$E$5:$E$219,"Secundari",'3000 Pirineu'!$G$5:$G$219,"Sí") | P40: =IF(L40+N40=0,0,(M40+O40)/(L40+N40))
B41: Conflent | C41: =COUNTIF('100 Cims FEEC'!$C$5:$C$526,B41) | D41: =COUNTIFS('100 Cims FEEC'!$C$5:$C$526,B41,'100 Cims FEEC'!$E$5:$E$526,"Essencial") | E41: =COUNTIFS('100 Cims FEEC'!$C$5:$C$526,B41,'100 Cims FEEC'!$E$5:$E$526,"Essencial",'100 Cims FEEC'!$G$5:$G$526,"Sí") | F41: =D41-E41 | G41: =COUNTIFS('100 Cims FEEC'!$C$5:$C$526,B41,'100 Cims FEEC'!$E$5:$E$526,"No essencial",'100 Cims FEEC'!$G$5:$G$526,"Sí") | H41: =IF(D41=0,"-",E41/D41) | K41: Z7 · Posets-Eriste | L41: =COUNTIFS('3000 Pirineu'!$D$5:$D$219,K41,'3000 Pirineu'!$E$5:$E$219,"Principal") | M41: =COUNTIFS('3000 Pirineu'!$D$5:$D$219,K41,'3000 Pirineu'!$E$5:$E$219,"Principal",'3000 Pirineu'!$G$5:$G$219,"Sí") | N41: =COUNTIFS('3000 Pirineu'!$D$5:$D$219,K41,'3000 Pirineu'!$E$5:$E$219,"Secundari") | O41: =COUNTIFS('3000 Pirineu'!$D$5:$D$219,K41,'3000 Pirineu'!$E$5:$E$219,"Secundari",'3000 Pirineu'!$G$5:$G$219,"Sí") | P41: =IF(L41+N41=0,0,(M41+O41)/(L41+N41))
B42: Garrigues | C42: =COUNTIF('100 Cims FEEC'!$C$5:$C$526,B42) | D42: =COUNTIFS('100 Cims FEEC'!$C$5:$C$526,B42,'100 Cims FEEC'!$E$5:$E$526,"Essencial") | E42: =COUNTIFS('100 Cims FEEC'!$C$5:$C$526,B42,'100 Cims FEEC'!$E$5:$E$526,"Essencial",'100 Cims FEEC'!$G$5:$G$526,"Sí") | F42: =D42-E42 | G42: =COUNTIFS('100 Cims FEEC'!$C$5:$C$526,B42,'100 Cims FEEC'!$E$5:$E$526,"No essencial",'100 Cims FEEC'!$G$5:$G$526,"Sí") | H42: =IF(D42=0,"-",E42/D42) | K42: Z8 · Clarabide-Perdiguero | L42: =COUNTIFS('3000 Pirineu'!$D$5:$D$219,K42,'3000 Pirineu'!$E$5:$E$219,"Principal") | M42: =COUNTIFS('3000 Pirineu'!$D$5:$D$219,K42,'3000 Pirineu'!$E$5:$E$219,"Principal",'3000 Pirineu'!$G$5:$G$219,"Sí") | N42: =COUNTIFS('3000 Pirineu'!$D$5:$D$219,K42,'3000 Pirineu'!$E$5:$E$219,"Secundari") | O42: =COUNTIFS('3000 Pirineu'!$D$5:$D$219,K42,'3000 Pirineu'!$E$5:$E$219,"Secundari",'3000 Pirineu'!$G$5:$G$219,"Sí") | P42: =IF(L42+N42=0,0,(M42+O42)/(L42+N42))
B43: Garrotxa | C43: =COUNTIF('100 Cims FEEC'!$C$5:$C$526,B43) | D43: =COUNTIFS('100 Cims FEEC'!$C$5:$C$526,B43,'100 Cims FEEC'!$E$5:$E$526,"Essencial") | E43: =COUNTIFS('100 Cims FEEC'!$C$5:$C$526,B43,'100 Cims FEEC'!$E$5:$E$526,"Essencial",'100 Cims FEEC'!$G$5:$G$526,"Sí") | F43: =D43-E43 | G43: =COUNTIFS('100 Cims FEEC'!$C$5:$C$526,B43,'100 Cims FEEC'!$E$5:$E$526,"No essencial",'100 Cims FEEC'!$G$5:$G$526,"Sí") | H43: =IF(D43=0,"-",E43/D43) | K43: Z9 · Maladeta-Aneto | L43: =COUNTIFS('3000 Pirineu'!$D$5:$D$219,K43,'3000 Pirineu'!$E$5:$E$219,"Principal") | M43: =COUNTIFS('3000 Pirineu'!$D$5:$D$219,K43,'3000 Pirineu'!$E$5:$E$219,"Principal",'3000 Pirineu'!$G$5:$G$219,"Sí") | N43: =COUNTIFS('3000 Pirineu'!$D$5:$D$219,K43,'3000 Pirineu'!$E$5:$E$219,"Secundari") | O43: =COUNTIFS('3000 Pirineu'!$D$5:$D$219,K43,'3000 Pirineu'!$E$5:$E$219,"Secundari",'3000 Pirineu'!$G$5:$G$219,"Sí") | P43: =IF(L43+N43=0,0,(M43+O43)/(L43+N43))
B44: Gironès | C44: =COUNTIF('100 Cims FEEC'!$C$5:$C$526,B44) | D44: =COUNTIFS('100 Cims FEEC'!$C$5:$C$526,B44,'100 Cims FEEC'!$E$5:$E$526,"Essencial") | E44: =COUNTIFS('100 Cims FEEC'!$C$5:$C$526,B44,'100 Cims FEEC'!$E$5:$E$526,"Essencial",'100 Cims FEEC'!$G$5:$G$526,"Sí") | F44: =D44-E44 | G44: =COUNTIFS('100 Cims FEEC'!$C$5:$C$526,B44,'100 Cims FEEC'!$E$5:$E$526,"No essencial",'100 Cims FEEC'!$G$5:$G$526,"Sí") | H44: =IF(D44=0,"-",E44/D44) | K44: Z10 · Besiberri | L44: =COUNTIFS('3000 Pirineu'!$D$5:$D$219,K44,'3000 Pirineu'!$E$5:$E$219,"Principal") | M44: =COUNTIFS('3000 Pirineu'!$D$5:$D$219,K44,'3000 Pirineu'!$E$5:$E$219,"Principal",'3000 Pirineu'!$G$5:$G$219,"Sí") | N44: =COUNTIFS('3000 Pirineu'!$D$5:$D$219,K44,'3000 Pirineu'!$E$5:$E$219,"Secundari") | O44: =COUNTIFS('3000 Pirineu'!$D$5:$D$219,K44,'3000 Pirineu'!$E$5:$E$219,"Secundari",'3000 Pirineu'!$G$5:$G$219,"Sí") | P44: =IF(L44+N44=0,0,(M44+O44)/(L44+N44))
B45: Lluçanès | C45: =COUNTIF('100 Cims FEEC'!$C$5:$C$526,B45) | D45: =COUNTIFS('100 Cims FEEC'!$C$5:$C$526,B45,'100 Cims FEEC'!$E$5:$E$526,"Essencial") | E45: =COUNTIFS('100 Cims FEEC'!$C$5:$C$526,B45,'100 Cims FEEC'!$E$5:$E$526,"Essencial",'100 Cims FEEC'!$G$5:$G$526,"Sí") | F45: =D45-E45 | G45: =COUNTIFS('100 Cims FEEC'!$C$5:$C$526,B45,'100 Cims FEEC'!$E$5:$E$526,"No essencial",'100 Cims FEEC'!$G$5:$G$526,"Sí") | H45: =IF(D45=0,"-",E45/D45) | K45: Z11 · Montcalm-Estats | L45: =COUNTIFS('3000 Pirineu'!$D$5:$D$219,K45,'3000 Pirineu'!$E$5:$E$219,"Principal") | M45: =COUNTIFS('3000 Pirineu'!$D$5:$D$219,K45,'3000 Pirineu'!$E$5:$E$219,"Principal",'3000 Pirineu'!$G$5:$G$219,"Sí") | N45: =COUNTIFS('3000 Pirineu'!$D$5:$D$219,K45,'3000 Pirineu'!$E$5:$E$219,"Secundari") | O45: =COUNTIFS('3000 Pirineu'!$D$5:$D$219,K45,'3000 Pirineu'!$E$5:$E$219,"Secundari",'3000 Pirineu'!$G$5:$G$219,"Sí") | P45: =IF(L45+N45=0,0,(M45+O45)/(L45+N45))
...

Sheet 100 Cims FEEC
A1: Repte dels 100 Cims · Llista FEEC
A2: 522 cims · 150 essencials · columnes grogues editables («Assolit» Sí/No i «Data», que es pot deixar en blanc) · ordenat per comarca i altitud
A4: Cim | B4: Altitud (m) | C4: Comarca principal | D4: Comarques / territoris | E4: Tipus | F4: Sostre comarcal | G4: Assolit | H4: Data | I4: Punt(s) al meu KMZ | J4: Latitud | K4: Longitud | L4: Fitxa FEEC | M4: Mapa | N4: Ascensions | O4: Dates de les ascensions
A5: Montagut d’Ancosa | B5: 963 | C5: Alt Camp | D5: Alt Camp | E5: No essencial | J5: 41.40688 | K5: 1.42226 | L5: Fitxa ↗ | M5: Mapa ↗
A6: El Cogulló de Cabra | B6: 881 | C6: Alt Camp | D6: Alt Camp | E6: Essencial | J6: 41.42904 | K6: 1.30576 | L6: Fitxa ↗ | M6: Mapa ↗
A7: El Tossal Gros | B7: 867 | C7: Alt Camp | D7: Alt Camp, Conca de Barberà | E7: Essencial | J7: 41.37536 | K7: 1.23939 | L7: Fitxa ↗ | M7: Mapa ↗
A8: La Cogulla | B8: 786 | C8: Alt Camp | D8: Alt Camp, Conca de Barberà | E8: No essencial | J8: 41.3488 | K8: 1.22483 | L8: Fitxa ↗ | M8: Mapa ↗
A9: Puigcabrer | B9: 524 | C9: Alt Camp | D9: Alt Camp | E9: No essencial | J9: 41.31533 | K9: 1.19129 | L9: Fitxa ↗ | M9: Mapa ↗
A10: Tossa Grossa de Montferri | B10: 387 | C10: Alt Camp | D10: Alt Camp | E10: Essencial | J10: 41.25345 | K10: 1.37048 | L10: Fitxa ↗ | M10: Mapa ↗
A11: Roc del Comptador | B11: 1451 | C11: Alt Empordà | D11: Alt Empordà, Vallespir | E11: Essencial | F11: Alt Empordà | J11: 42.42279 | K11: 2.72729 | L11: Fitxa ↗ | M11: Mapa ↗
A12: Puig de les Bruixes | B12: 1391 | C12: Alt Empordà | D12: Alt Empordà, Garrotxa | E12: No essencial | J12: 42.32449 | K12: 2.5555 | L12: Fitxa ↗ | M12: Mapa ↗
A13: Bassegoda | B13: 1373 | C13: Alt Empordà | D13: Alt Empordà, Garrotxa | E13: Essencial | J13: 42.3128 | K13: 2.63073 | L13: Fitxa ↗ | M13: Mapa ↗
A14: Puig Neulós | B14: 1257 | C14: Alt Empordà | D14: Alt Empordà, Rosselló | E14: Essencial | J14: 42.4821 | K14: 2.94711 | L14: Fitxa ↗ | M14: Mapa ↗
A15: El Mont | B15: 1125 | C15: Alt Empordà | D15: Alt Empordà | E15: Essencial | J15: 42.25885 | K15: 2.7063 | L15: Fitxa ↗ | M15: Mapa ↗
A16: Puig Falcó | B16: 1097 | C16: Alt Empordà | D16: Alt Empordà | E16: No essencial | J16: 42.37529 | K16: 2.66709 | L16: Fitxa ↗ | M16: Mapa ↗
A17: Tossa d’Espinau | B17: 1087 | C17: Alt Empordà | D17: Alt Empordà, Garrotxa | E17: No essencial | J17: 42.27343 | K17: 2.69285 | L17: Fitxa ↗ | M17: Mapa ↗
A18: Puig de la Gavarra | B18: 1057 | C18: Alt Empordà | D18: Alt Empordà | E18: No essencial | J18: 42.36073 | K18: 2.69685 | L18: Fitxa ↗ | M18: Mapa ↗
A19: Pic de Sallafort | B19: 994 | C19: Alt Empordà | D19: Alt Empordà, Rosselló | E19: No essencial | J19: 42.47347 | K19: 3.03804 | L19: Fitxa ↗ | M19: Mapa ↗
A20: Puig dels Pruners | B20: 832 | C20: Alt Empordà | D20: Alt Empordà, Vallespir | E20: No essencial | J20: 42.428 | K20: 2.80294 | L20: Fitxa ↗ | M20: Mapa ↗
A21: Puig d’en Jordà | B21: 754 | C21: Alt Empordà | D21: Alt Empordà, Rosselló | E21: No essencial | J21: 42.42776 | K21: 3.08205 | L21: Fitxa ↗ | M21: Mapa ↗
A22: Castell Saverdera | B22: 682 | C22: Alt Empordà | D22: Alt Empordà | E22: Essencial | J22: 42.31997 | K22: 3.16782 | L22: Fitxa ↗ | M22: Mapa ↗
A23: Querroig | B23: 672 | C23: Alt Empordà | D23: Alt Empordà, Rosselló | E23: No essencial | J23: 42.43826 | K23: 3.12093 | L23: Fitxa ↗ | M23: Mapa ↗
... A32: Puig d’Agulles | B32: 653 | C32: Alt Penedès | D32: Alt Penedès, Baix Llobregat | E32: No essencial | J32: 41.40808 | K32: 1.88498 | L32: Fitxa ↗ | M32: Mapa ↗
A33: Puig de la Mola | B33: 534 | C33: Alt Penedès | D33: Alt Penedès, Baix Llobregat, Garraf | E33: No essencial | F33: Garraf | J33: 41.31932 | K33: 1.84785 | L33: Fitxa ↗ | M33: Mapa ↗
A34: El Castellot | B34: 465 | C34: Alt Penedès | D34: Alt Penedès | E34: Essencial | J34: 41.33759 | K34: 1.57863 | L34: Fitxa ↗ | M34: Mapa ↗
A35: Puig de l’Àliga | B35: 464 | C35: Alt Penedès | D35: Alt Penedès, Garraf | E35: Essencial | J35: 41.28387 | K35: 1.69738 | L35: Fitxa ↗ | M35: Mapa ↗
A36: Penya del Papiol | B36: 381 | C36: Alt Penedès | D36: Alt Penedès | E36: Essencial | J36: 41.32295 | K36: 1.74385 | L36: Fitxa ↗ | M36: Mapa ↗
A37: Pic de Salòria | B37: 2789 | C37: Alt Urgell | D37: Alt Urgell, Pallars Sobirà | E37: Essencial | F37: Alt Urgell | J37: 42.51445 | K37: 1.38514 | L37: Fitxa ↗ | M37: Mapa ↗
A38: Monturull | B38: 2760 | C38: Alt Urgell | D38: Alt Urgell, Andorra, Cerdanya | E38: Essencial | J38: 42.44995 | K38: 1.581 | L38: Fitxa ↗ | M38: Mapa ↗
A39: Vulturó | B39: 2649 | C39: Alt Urgell | D39: Alt Urgell | E39: Essencial | J39: 42.28578 | K39: 1.63643 | L39: Fitxa ↗ | M39: Mapa ↗
A40: Pic de Costa Cabirolera | B40: 2604 | C40: Alt Urgell | D40: Alt Urgell, Berguedà, Cerdanya | E40: No essencial | F40: Berguedà | J40: 42.28146 | K40: 1.67042 | L40: Fitxa ↗ | M40: Mapa ↗
A41: Torreta del Cadí | B41: 2562 | C41: Alt Urgell | D41: Alt Urgell | E41: No essencial | J41: 42.28707 | K41: 1.5842 | L41: Fitxa ↗ | M41: Mapa ↗
A42: Turó Punçó | B42: 2493 | C42: Alt Urgell | D42: Alt Urgell, Cerdanya | E42: No essencial | J42: 42.42455 | K42: 1.60099 | L42: Fitxa ↗ | M42: Mapa ↗
A43: Bony de la Pica o Pica d’Os | B43: 2405 | C43: Alt Urgell | D43: Alt Urgell, Andorra | E43: Essencial | J43: 42.5048 | K43: 1.4604 | L43: Fitxa ↗ | M43: Mapa ↗
A44: Pedró dels Quatre Batlles | B44: 2387 | C44: Alt Urgell | D44: Alt Urgell, Solsonès | E44: No essencial | F44: Solsonès | J44: 42.1848 | K44: 1.52091 | L44: Fitxa ↗ | M44: Mapa ↗
A45: Cap del Verd | B45: 2284 | C45: Alt Urgell | D45: Alt Urgell, Berguedà, Solsonès | E45: Essencial | J45: 42.20081 | K45: 1.61371 | L45: Fitxa ↗ | M45: Mapa ↗
A46: Mirador del Pla de Llet | B46: 2141 | C46: Alt Urgell | D46: Alt Urgell, Cerdanya | E46: No essencial | J46: 42.40455 | K46: 1.63295 | L46: Fitxa ↗ | M46: Mapa ↗
A47: El Cadinell | B47: 2113 | C47: Alt Urgell | D47: Alt Urgell | E47: No essencial | J47: 42.26439 | K47: 1.59782 | L47: Fitxa ↗ | M47: Mapa ↗
A48: Roc Roi | B48: 2020 | C48: Alt Urgell | D48: Alt Urgell | E48: No essencial | J48: 42.43535 | K48: 1.33829 | L48: Fitxa ↗ | M48: Mapa ↗
A49: Les Piques | B49: 1969 | C49: Alt Urgell | D49: Alt Urgell | E49: No essencial | J49: 42.32097 | K49: 1.17585 | L49: Fitxa ↗ | M49: Mapa ↗
...

Sheet 3000 Pirineu
A1: Els 3000 del Pirineu · llista UIAA
A2: 212 tresmils (129 principals + 83 secundaris, llista Buyse/UIAA) + 3 tresmils catalans fora de la llista · columnes grogues editables · ordenat per zona i altitud
A4: Nº UIAA | B4: Cim | C4: Altitud (m) | D4: Zona | E4: Llista UIAA | F4: Tresmil català | G4: Assolit | H4: Data | I4: Punt(s) al meu KMZ | J4: Ascensions | K4: Dates de les ascensions
A5: 001 | B5: Balaitus | C5: 3144 | D5: Z1 · Balaitús-Infiernos | E5: Principal | F5: No
A6: 006 | B6: Infierno Central | C6: 3083 | D6: Z1 · Balaitús-Infiernos | E6: Principal | F6: No
A7: 007 | B7: Infierno Oriental | C7: 3076 | D7: Z1 · Balaitús-Infiernos | E7: Principal | F7: No
A8: 005 | B8: Infierno Occidental | C8: 3073 | D8: Z1 · Balaitús-Infiernos | E8: Principal | F8: No
A9: 002 | B9: Frondella | C9: 3071 | D9: Z1 · Balaitús-Infiernos | E9: Principal | F9: No
A10: 04 | B10: Frondella N | C10: 3062 | D10: Z1 · Balaitús-Infiernos | E10: Secundari | F10: No
A11: 05 | B11: Frondella Central | C11: 3055 | D11: Z1 · Balaitús-Infiernos | E11: Secundari | F11: No
A12: 009 | B12: Garmo Negro | C12: 3051 | D12: Z1 · Balaitús-Infiernos | E12: Principal | F12: No
A13: 01 | B13: Torre Costerillou | C13: 3049 | D13: Z1 · Balaitús-Infiernos | E13: Secundari | F13: No
A14: 011 | B14: Argualas | C14: 3046 | D14: Z1 · Balaitús-Infiernos | E14: Principal | F14: No
A15: 010 | B15: Algas | C15: 3036 | D15: Z1 · Balaitús-Infiernos | E15: Principal | F15: No
A16: 07 | B16: Algas N | C16: 3032 | D16: Z1 · Balaitús-Infiernos | E16: Secundari | F16: No
... A219: 83 | B219: Rodó de Canalbona | C219: 3004 | D219: Z11 · Montcalm-Estats | E219: Secundari | F219: Sí

Sheet 3000 Pirineu català
A1: Els 3000 del Pirineu català
A2: 16 tresmils de Catalunya (13 vigents + 3 de baixa per quedar per sota de 3.000 m amb les alçades ICGC) · «Assolit» i «Data» es llegeixen de la pestanya «3000 Pirineu»
A4: Cim | B4: Altitud ICGC (m) | C4: Zona | D4: Estat | E4: Llista UIAA | F4: Nom a «3000 Pirineu» | G4: Assolit | H4: Data
A5: Pica d'Estats | B5: 3143.45 | C5: Z11 · Montcalm-Estats | D5: Vigent | E5: Principal | F5: Pica d'Estats | G5: =IFERROR(INDEX('3000 Pirineu'!$G$5:$G$219,MATCH(F5,'3000 Pirineu'!$B$5:$B$219,0)),"No") | H5: =IFERROR(IF(INDEX('3000 Pirineu'!$H$5:$H$219,MATCH(F5,'3000 Pirineu'!$B$5:$B$219,0))="","",INDEX('3000 Pirineu'!$H$5:$H$219,MATCH(F5,'3000 Pirineu'!$B$5:$B$219,0))),"")
A6: Pic Verdaguer | B6: 3129.4 | C6: Z11 · Montcalm-Estats | D6: Vigent | E6: Principal | F6: Pico Verdaguer | G6: =IFERROR(INDEX('3000 Pirineu'!$G$5:$G$219,MATCH(F6,'3000 Pirineu'!$B$5:$B$219,0)),"No") | H6: =IFERROR(IF(INDEX('3000 Pirineu'!$H$5:$H$219,MATCH(F6,'3000 Pirineu'!$B$5:$B$219,0))="","",INDEX('3000 Pirineu'!$H$5:$H$219,MATCH(F6,'3000 Pirineu'!$B$5:$B$219,0))),"")
A7: Punta Gabarró | B7: 3114.6 | C7: Z11 · Montcalm-Estats | D7: Vigent | E7: Secundari | F7: Punta Gabarró | G7: =IFERROR(INDEX('3000 Pirineu'!$G$5:$G$219,MATCH(F7,'3000 Pirineu'!$B$5:$B$219,0)),"No") | H7: =IFERROR(IF(INDEX('3000 Pirineu'!$H$5:$H$219,MATCH(F7,'3000 Pirineu'!$B$5:$B$219,0))="","",INDEX('3000 Pirineu'!$H$5:$H$219,MATCH(F7,'3000 Pirineu'!$B$5:$B$219,0))),"")
A8: Pic de Sotllo | B8: 3072.77 | C8: Z11 · Montcalm-Estats | D8: Vigent | E8: Principal | F8: Pico de Sotllo | G8: =IFERROR(INDEX('3000 Pirineu'!$G$5:$G$219,MATCH(F8,'3000 Pirineu'!$B$5:$B$219,0)),"No") | H8: =IFERROR(IF(INDEX('3000 Pirineu'!$H$5:$H$219,MATCH(F8,'3000 Pirineu'!$B$5:$B$219,0))="","",INDEX('3000 Pirineu'!$H$5:$H$219,MATCH(F8,'3000 Pirineu'!$B$5:$B$219,0))),"")
A9: Sotllo Nord | B9: 3058.2 | C9: Z11 · Montcalm-Estats | D9: Vigent | E9: No (només llista catalana) | F9: Sotllo Nord | G9: =IFERROR(INDEX('3000 Pirineu'!$G$5:$G$219,MATCH(F9,'3000 Pirineu'!$B$5:$B$219,0)),"No") | H9: =IFERROR(IF(INDEX('3000 Pirineu'!$H$5:$H$219,MATCH(F9,'3000 Pirineu'!$B$5:$B$219,0))="","",INDEX('3000 Pirineu'!$H$5:$H$219,MATCH(F9,'3000 Pirineu'!$B$5:$B$219,0))),"")
A10: Pic de Comaloforno | B10: 3029.18 | C10: Z10 · Besiberri | D10: Vigent | E10: Principal | F10: Comaloforno | G10: =IFERROR(INDEX('3000 Pirineu'!$G$5:$G$219,MATCH(F10,'3000 Pirineu'!$B$5:$B$219,0)),"No") | H10: =IFERROR(IF(INDEX('3000 Pirineu'!$H$5:$H$219,MATCH(F10,'3000 Pirineu'!$B$5:$B$219,0))="","",INDEX('3000 Pirineu'!$H$5:$H$219,MATCH(F10,'3000 Pirineu'!$B$5:$B$219,0))),"")
A11: Besiberri Sud | B11: 3023.4 | C11: Z10 · Besiberri | D11: Vigent | E11: Principal | F11: Besiberri S | G11: =IFERROR(INDEX('3000 Pirineu'!$G$5:$G$219,MATCH(F11,'3000 Pirineu'!$B$5:$B$219,0)),"No") | H11: =IFERROR(IF(INDEX('3000 Pirineu'!$H$5:$H$219,MATCH(F11,'3000 Pirineu'!$B$5:$B$219,0))="","",INDEX('3000 Pirineu'!$H$5:$H$219,MATCH(F11,'3000 Pirineu'!$B$5:$B$219,0))),"")
A12: Punta Alta de Comalesbienes | B12: 3014.02 | C12: Z10 · Besiberri | D12: Vigent | E12: Principal | F12: Punta Alta (Comalesbienes) | G12: =IFERROR(INDEX('3000 Pirineu'!$G$5:$G$219,MATCH(F12,'3000 Pirineu'!$B$5:$B$219,0)),"No") | H12: =IFERROR(IF(INDEX('3000 Pirineu'!$H$5:$H$219,MATCH(F12,'3000 Pirineu'!$B$5:$B$219,0))="","",INDEX('3000 Pirineu'!$H$5:$H$219,MATCH(F12,'3000 Pirineu'!$B$5:$B$219,0))),"")
A13: Agulla Sud de Malavesina | B13: 3011.7 | C13: Z10 · Besiberri | D13: Vigent | E13: No (només llista catalana) | F13: Agulla Sud de Malavesina | G13: =IFERROR(INDEX('3000 Pirineu'!$G$5:$G$219,MATCH(F13,'3000 Pirineu'!$B$5:$B$219,0)),"No") | H13: =IFERROR(IF(INDEX('3000 Pirineu'!$H$5:$H$219,MATCH(F13,'3000 Pirineu'!$B$5:$B$219,0))="","",INDEX('3000 Pirineu'!$H$5:$H$219,MATCH(F13,'3000 Pirineu'!$B$5:$B$219,0))),"")
A14: Tuc de Molières | B14: 3010.08 | C14: Z9 · Maladeta-Aneto | D14: Vigent | E14: Principal | F14: Tuc de Mulleres (Molières) | G14: =IFERROR(INDEX('3000 Pirineu'!$G$5:$G$219,MATCH(F14,'3000 Pirineu'!$B$5:$B$219,0)),"No") | H14: =IFERROR(IF(INDEX('3000 Pirineu'!$H$5:$H$219,MATCH(F14,'3000 Pirineu'!$B$5:$B$219,0))="","",INDEX('3000 Pirineu'!$H$5:$H$219,MATCH(F14,'3000 Pirineu'!$B$5:$B$219,0))),"")
A15: Agulla Nord de Malavesina | B15: 3009.9 | C15: Z10 · Besiberri | D15: Vigent | E15: No (només llista catalana) | F15: Agulla Nord de Malavesina | G15: =IFERROR(INDEX('3000 Pirineu'!$G$5:$G$219,MATCH(F15,'3000 Pirineu'!$B$5:$B$219,0)),"No") | H15: =IFERROR(IF(INDEX('3000 Pirineu'!$H$5:$H$219,MATCH(F15,'3000 Pirineu'!$B$5:$B$219,0))="","",INDEX('3000 Pirineu'!$H$5:$H$219,MATCH(F15,'3000 Pirineu'!$B$5:$B$219,0))),"")
A16: Besiberri Nord | B16: 3008.27 | C16: Z10 · Besiberri | D16: Vigent | E16: Principal | F16: Besiberri N | G16: =IFERROR(INDEX('3000 Pirineu'!$G$5:$G$219,MATCH(F16,'3000 Pirineu'!$B$5:$B$219,0)),"No") | H16: =IFERROR(IF(INDEX('3000 Pirineu'!$H$5:$H$219,MATCH(F16,'3000 Pirineu'!$B$5:$B$219,0))="","",INDEX('3000 Pirineu'!$H$5:$H$219,MATCH(F16,'3000 Pirineu'!$B$5:$B$219,0))),"")
... A20: Besiberri del Mig S | B20: 2995.2 | C20: Z10 · Besiberri | D20: Baixa (<3000 m) | E20: Principal | F20: Besiberri del Mig S | G20: =IFERROR(INDEX('3000 Pirineu'!$G$5:$G$219,MATCH(F20,'3000 Pirineu'!$B$5:$B$219,0)),"No") | H20: =IFERROR(IF(INDEX('3000 Pirineu'!$H$5:$H$219,MATCH(F20,'3000 Pirineu'!$B$5:$B$219,0))="","",INDEX('3000 Pirineu'!$H$5:$H$219,MATCH(F20,'3000 Pirineu'!$B$5:$B$219,0))),"")

Sheet 4000 Alps
A1: Els 4000 dels Alps · llista UIAA
A2: 128 cims (82 principals + 46 secundaris, llista UIAA de 1994) · columnes grogues editables · ordenat per altitud
A4: Nº UIAA | B4: Cim | C4: Altitud (m) | D4: Massís | E4: País | F4: Llista UIAA | G4: Assolit | H4: Data | I4: Ascensions | J4: Dates de les ascensions | K4: Latitud | L4: Longitud | M4: Mapa
A5: 1 | B5: Mont Blanc | C5: 4809 | D5: Massís del Mont Blanc | E5: FR/IT | F5: Principal | K5: 45.8328 | L5: 6.865 | M5: Mapa ↗
A6: 2 | B6: Mont Blanc de Courmayeur | C6: 4748 | D6: Massís del Mont Blanc | E6: FR/IT | F6: Principal | K6: 45.8289 | L6: 6.8694 | M6: Mapa ↗
A7: — | B7: Rocher de la Tournette | C7: 4677 | D7: Massís del Mont Blanc | E7: FR/IT | F7: Secundari | K7: 45.83278 | L7: 6.85944 | M7: Mapa ↗
A8: 3 | B8: Dufourspitze | C8: 4634 | D8: Monte Rosa | E8: CH/IT | F8: Principal | K8: 45.9368 | L8: 7.8671 | M8: Mapa ↗
A9: — | B9: Dunantspitze | C9: 4632 | D9: Monte Rosa | E9: CH | F9: Secundari
A10: — | B10: Grenzgipfel | C10: 4618 | D10: Monte Rosa | E10: CH/IT | F10: Secundari | K10: 45.93675 | L10: 7.868 | M10: Mapa ↗
A11: 4 | B11: Nordend | C11: 4609 | D11: Monte Rosa | E11: CH/IT | F11: Principal | K11: 45.9422 | L11: 7.87 | M11: Mapa ↗
A12: 5 | B12: Zumsteinspitze | C12: 4563 | D12: Monte Rosa | E12: CH/IT | F12: Principal | K12: 45.9319 | L12: 7.8714 | M12: Mapa ↗
A13: 6 | B13: Signalkuppe (Punta Gnifetti) | C13: 4554 | D13: Monte Rosa | E13: CH/IT | F13: Principal | K13: 45.9272 | L13: 7.8769 | M13: Mapa ↗
A14: — | B14: Les Bosses | C14: 4547 | D14: Massís del Mont Blanc | E14: FR/IT | F14: Secundari | K14: 45.835028 | L14: 6.856078 | M14: Mapa ↗
A15: 7 | B15: Dom | C15: 4545 | D15: Mischabel | E15: CH | F15: Principal | K15: 46.095 | L15: 7.86 | M15: Mapa ↗
A16: 8 | B16: Liskamm Est | C16: 4527 | D16: Alps Penins | E16: CH/IT | F16: Principal | K16: 45.9225 | L16: 7.8356 | M16: Mapa ↗
A17: — | B17: La Grande Bosse | C17: 4513 | D17: Massís del Mont Blanc | E17: FR/IT | F17: Secundari
A18: 9 | B18: Weisshorn | C18: 4505 | D18: Alps Penins | E18: CH | F18: Principal | K18: 46.1017 | L18: 7.7161 | M18: Mapa ↗
A19: 10 | B19: Täschhorn | C19: 4491 | D19: Mischabel | E19: CH | F19: Principal | K19: 46.0836 | L19: 7.8572 | M19: Mapa ↗
A20: 11 | B20: Liskamm Oest | C20: 4479 | D20: Alps Penins | E20: CH/IT | F20: Principal | K20: 45.9265 | L20: 7.8233 | M20: Mapa ↗
A21: 12 | B21: Matterhorn (Cervino) | C21: 4478 | D21: Alps Penins | E21: CH/IT | F21: Principal | K21: 45.9764 | L21: 7.6586 | M21: Mapa ↗
A22: — | B22: Cervino, cim italià | C22: 4476 | D22: Alps Penins | E22: CH/IT | F22: Secundari
A23: 13 | B23: Picco Luigi Amedeo | C23: 4469 | D23: Massís del Mont Blanc | E23: IT | F23: Principal | K23: 45.8244 | L23: 6.8682 | M23: Mapa ↗
A24: — | B24: Dom (Grosser Gendarm) | C24: 4468 | D24: Mischabel | E24: CH | F24: Secundari
A25: 14 | B25: Mont Maudit | C25: 4465 | D25: Massís del Mont Blanc | E25: FR/IT | F25: Principal | K25: 45.8478 | L25: 6.8758 | M25: Mapa ↗
A26: 15 | B26: Parrotspitze | C26: 4432 | D26: Monte Rosa | E26: CH/IT | F26: Principal | K26: 45.9197 | L26: 7.8714 | M26: Mapa ↗
A27: 16 | B27: Dent Blanche | C27: 4357 | D27: Alps Penins | E27: CH | F27: Principal | K27: 46.0342 | L27: 7.6119 | M27: Mapa ↗
A28: — | B28: Aiguille de la Belle Étoile | C28: 4349 | D28: Massís del Mont Blanc | E28: IT | F28: Secundari
A29: 17 | B29: Ludwigshöhe | C29: 4341 | D29: Monte Rosa | E29: CH/IT | F29: Principal | K29: 45.9172 | L29: 7.8622 | M29: Mapa ↗
A30: — | B30: Grand Gendarme (Weisshorn) | C30: 4331 | D30: Alps Penins | E30: CH | F30: Secundari | K30: 46.1083 | L30: 7.7127 | M30: Mapa ↗
A31: 18 | B31: Nadelhorn | C31: 4327 | D31: Mischabel | E31: CH | F31: Principal | K31: 46.1088 | L31: 7.8642 | M31: Mapa ↗
A32: 19 | B32: Schwarzhorn (Corno Nero) | C32: 4322 | D32: Monte Rosa | E32: IT | F32: Principal | K32: 45.9149 | L32: 7.862 | M32: Mapa ↗
A33: 20 | B33: Grand Combin de Grafeneire | C33: 4314 | D33: Grand Combin | E33: CH | F33: Principal | K33: 45.9375 | L33: 7.2992 | M33: Mapa ↗
A34: 21 | B34: Dôme du Goûter | C34: 4304 | D34: Massís del Mont Blanc | E34: FR/IT | F34: Principal | K34: 45.8428 | L34: 6.8433 | M34: Mapa ↗
A35: 22 | B35: Lenzspitze | C35: 4294 | D35: Mischabel | E35: CH | F35: Principal | K35: 46.1046 | L35: 7.8684 | M35: Mapa ↗
A36: — | B36: Pointe Mieulet | C36: 4287 | D36: Massís del Mont Blanc | E36: FR | F36: Secundari | K36: 45.850457 | L36: 6.872121 | M36: Mapa ↗
A37: 23 | B37: Finsteraarhorn | C37: 4274 | D37: Alps Bernesos | E37: CH | F37: Principal | K37: 46.5375 | L37: 8.126 | M37: Mapa ↗
A38: — | B38: Liskammnase | C38: 4272 | D38: Alps Penins | E38: CH/IT | F38: Secundari | K38: 45.916671 | L38: 7.835355 | M38: Mapa ↗
A39: — | B39: Pointe Bayeux | C39: 4258 | D39: Massís del Mont Blanc | E39: FR | F39: Secundari | K39: 45.84639 | L39: 6.84389 | M39: Mapa ↗
A40: 24 | B40: Mont Blanc du Tacul | C40: 4248 | D40: Massís del Mont Blanc | E40: FR | F40: Principal | K40: 45.8564 | L40: 6.8878 | M40: Mapa ↗
A41: — | B41: Mont Blanc du Tacul (punt E) | C41: 4247 | D41: Massís del Mont Blanc | E41: FR | F41: Secundari
...

Sheet Sostres comarcals
A1: Sostres comarcals de Catalunya
A2: 43 sostres (un per comarca) · si el sostre és a la llista dels 100 Cims, «Assolit» i «Data» es llegeixen de «100 Cims FEEC»; si no, són editables
A4: Comarca | B4: Cim | C4: Altitud (m) | D4: Serra / zona | E4: A la llista 100 Cims | F4: Nom a «100 Cims» | G4: Assolit | H4: Data
A5: Pallars Sobirà | B5: Pica d'Estats | C5: 3143.5 | D5: Pirineu | E5: Essencial | F5: Pica d’Estats | G5: =IFERROR(INDEX('100 Cims FEEC'!$G$5:$G$526,MATCH(F5,'100 Cims FEEC'!$A$5:$A$526,0)),"No") | H5: =IFERROR(IF(INDEX('100 Cims FEEC'!$H$5:$H$526,MATCH(F5,'100 Cims FEEC'!$A$5:$A$526,0))="","",INDEX('100 Cims FEEC'!$H$5:$H$526,MATCH(F5,'100 Cims FEEC'!$A$5:$A$526,0))),"")
A6: Alta Ribagorça | B6: Pic de Comaloforno | C6: 3029.2 | D6: Pirineu | E6: Essencial | F6: Pic de Comaloforno | G6: =IFERROR(INDEX('100 Cims FEEC'!$G$5:$G$526,MATCH(F6,'100 Cims FEEC'!$A$5:$A$526,0)),"No") | H6: =IFERROR(IF(INDEX('100 Cims FEEC'!$H$5:$H$526,MATCH(F6,'100 Cims FEEC'!$A$5:$A$526,0))="","",INDEX('100 Cims FEEC'!$H$5:$H$526,MATCH(F6,'100 Cims FEEC'!$A$5:$A$526,0))),"")
A7: Val d'Aran | B7: Tuc de Molières | C7: 3010.1 | D7: Pirineu | E7: Essencial | F7: Tuc de Molières | G7: =IFERROR(INDEX('100 Cims FEEC'!$G$5:$G$526,MATCH(F7,'100 Cims FEEC'!$A$5:$A$526,0)),"No") | H7: =IFERROR(IF(INDEX('100 Cims FEEC'!$H$5:$H$526,MATCH(F7,'100 Cims FEEC'!$A$5:$A$526,0))="","",INDEX('100 Cims FEEC'!$H$5:$H$526,MATCH(F7,'100 Cims FEEC'!$A$5:$A$526,0))),"")
A8: Pallars Jussà | B8: Pic de Peguera | C8: 2982.7 | D8: Pirineu | E8: Essencial | F8: Pic de Peguera | G8: =IFERROR(INDEX('100 Cims FEEC'!$G$5:$G$526,MATCH(F8,'100 Cims FEEC'!$A$5:$A$526,0)),"No") | H8: =IFERROR(IF(INDEX('100 Cims FEEC'!$H$5:$H$526,MATCH(F8,'100 Cims FEEC'!$A$5:$A$526,0))="","",INDEX('100 Cims FEEC'!$H$5:$H$526,MATCH(F8,'100 Cims FEEC'!$A$5:$A$526,0))),"")
A9: Cerdanya | B9: Puigpedrós | C9: 2915 | D9: Pirineu | E9: Essencial | F9: Puigpedrós | G9: =IFERROR(INDEX('100 Cims FEEC'!$G$5:$G$526,MATCH(F9,'100 Cims FEEC'!$A$5:$A$526,0)),"No") | H9: =IFERROR(IF(INDEX('100 Cims FEEC'!$H$5:$H$526,MATCH(F9,'100 Cims FEEC'!$A$5:$A$526,0))="","",INDEX('100 Cims FEEC'!$H$5:$H$526,MATCH(F9,'100 Cims FEEC'!$A$5:$A$526,0))),"")
A10: Ripollès | B10: Puigmal | C10: 2909.8 | D10: Pirineu | E10: Essencial | F10: Puigmal | G10: =IFERROR(INDEX('100 Cims FEEC'!$G$5:$G$526,MATCH(F10,'100 Cims FEEC'!$A$5:$A$526,0)),"No") | H10: =IFERROR(IF(INDEX('100 Cims FEEC'!$H$5:$H$526,MATCH(F10,'100 Cims FEEC'!$A$5:$A$526,0))="","",INDEX('100 Cims FEEC'!$H$5:$H$526,MATCH(F10,'100 Cims FEEC'!$A$5:$A$526,0))),"")
A11: Alt Urgell | B11: Pic de Salòria | C11: 2789 | D11: Pirineu | E11: Essencial | F11: Pic de Salòria | G11: =IFERROR(INDEX('100 Cims FEEC'!$G$5:$G$526,MATCH(F11,'100 Cims FEEC'!$A$5:$A$526,0)),"No") | H11: =IFERROR(IF(INDEX('100 Cims FEEC'!$H$5:$H$526,MATCH(F11,'100 Cims FEEC'!$A$5:$A$526,0))="","",INDEX('100 Cims FEEC'!$H$5:$H$526,MATCH(F11,'100 Cims FEEC'!$A$5:$A$526,0))),"")
A12: Berguedà | B12: Pic de Costa Cabirolera | C12: 2604.4 | D12: Serra del Cadí | E12: No essencial | F12: Pic de Costa Cabirolera | G12: =IFERROR(INDEX('100 Cims FEEC'!$G$5:$G$526,MATCH(F12,'100 Cims FEEC'!$A$5:$A$526,0)),"No") | H12: =IFERROR(IF(INDEX('100 Cims FEEC'!$H$5:$H$526,MATCH(F12,'100 Cims FEEC'!$A$5:$A$526,0))="","",INDEX('100 Cims FEEC'!$H$5:$H$526,MATCH(F12,'100 Cims FEEC'!$A$5:$A$526,0))),"")
A13: Solsonès | B13: Pedró dels Quatre Batlles | C13: 2383 | D13: Port del Comte | E13: No essencial | F13: Pedró dels Quatre Batlles | G13: =IFERROR(INDEX('100 Cims FEEC'!$G$5:$G$526,MATCH(F13,'100 Cims FEEC'!$A$5:$A$526,0)),"No") | H13: =IFERROR(IF(INDEX('100 Cims FEEC'!$H$5:$H$526,MATCH(F13,'100 Cims FEEC'!$A$5:$A$526,0))="","",INDEX('100 Cims FEEC'!$H$5:$H$526,MATCH(F13,'100 Cims FEEC'!$A$5:$A$526,0))),"")
A14: Vallès Oriental | B14: Turó de l'Home | C14: 1705.78 | D14: Montseny | E14: No essencial | F14: Turó de l’Home | G14: =IFERROR(INDEX('100 Cims FEEC'!$G$5:$G$526,MATCH(F14,'100 Cims FEEC'!$A$5:$A$526,0)),"No") | H14: =IFERROR(IF(INDEX('100 Cims FEEC'!$H$5:$H$526,MATCH(F14,'100 Cims FEEC'!$A$5:$A$526,0))="","",INDEX('100 Cims FEEC'!$H$5:$H$526,MATCH(F14,'100 Cims FEEC'!$A$5:$A$526,0))),"")
A15: Selva | B15: Les Agudes | C15: 1705.5 | D15: Montseny | E15: Essencial | F15: Les Agudes | G15: =IFERROR(INDEX('100 Cims FEEC'!$G$5:$G$526,MATCH(F15,'100 Cims FEEC'!$A$5:$A$526,0)),"No") | H15: =IFERROR(IF(INDEX('100 Cims FEEC'!$H$5:$H$526,MATCH(F15,'100 Cims FEEC'!$A$5:$A$526,0))="","",INDEX('100 Cims FEEC'!$H$5:$H$526,MATCH(F15,'100 Cims FEEC'!$A$5:$A$526,0))),"")
A16: Osona | B16: Matagalls | C16: 1697.22 | D16: Montseny | E16: Essencial | F16: Matagalls | G16: =IFERROR(INDEX('100 Cims FEEC'!$G$5:$G$526,MATCH(F16,'100 Cims FEEC'!$A$5:$A$526,0)),"No") | H16: =IFERROR(IF(INDEX('100 Cims FEEC'!$H$5:$H$526,MATCH(F16,'100 Cims FEEC'!$A$5:$A$526,0))="","",INDEX('100 Cims FEEC'!$H$5:$H$526,MATCH(F16,'100 Cims FEEC'!$A$5:$A$526,0))),"")
A17: Noguera | B17: Tossal de les Torretes | C17: 1676.4 | D17: Montsec de Rúbies | E17: No
A18: Garrotxa | B18: Comanegra | C18: 1557.4 | D18: Pirineu | E18: Essencial | F18: Comanegra | G18: =IFERROR(INDEX('100 Cims FEEC'!$G$5:$G$526,MATCH(F18,'100 Cims FEEC'!$A$5:$A$526,0)),"No") | H18: =IFERROR(IF(INDEX('100 Cims FEEC'!$H$5:$H$526,MATCH(F18,'100 Cims FEEC'!$A$5:$A$526,0))="","",INDEX('100 Cims FEEC'!$H$5:$H$526,MATCH(F18,'100 Cims FEEC'!$A$5:$A$526,0))),"")
A19: Alt Empordà | B19: Roc del Comptador | C19: 1451 | D19: Pirineu-Les Salines | E19: Essencial | F19: Roc del Comptador | G19: =IFERROR(INDEX('100 Cims FEEC'!$G$5:$G$526,MATCH(F19,'100 Cims FEEC'!$A$5:$A$526,0)),"No") | H19: =IFERROR(IF(INDEX('100 Cims FEEC'!$H$5:$H$526,MATCH(F19,'100 Cims FEEC'!$A$5:$A$526,0))="","",INDEX('100 Cims FEEC'!$H$5:$H$526,MATCH(F19,'100 Cims FEEC'!$A$5:$A$526,0))),"")
A20: Baix Ebre | B20: Caro | C20: 1440.6 | D20: Ports de Tortosa-Beseit | E20: Essencial | F20: Caro | G20: =IFERROR(INDEX('100 Cims FEEC'!$G$5:$G$526,MATCH(F20,'100 Cims FEEC'!$A$5:$A$526,0)),"No") | H20: =IFERROR(IF(INDEX('100 Cims FEEC'!$H$5:$H$526,MATCH(F20,'100 Cims FEEC'!$A$5:$A$526,0))="","",INDEX('100 Cims FEEC'!$H$5:$H$526,MATCH(F20,'100 Cims FEEC'!$A$5:$A$526,0))),"")
A21: Montsià | B21: Tossal dels Tres Reis | C21: 1350.3 | D21: Ports de Tortosa-Beseit | E21: Essencial | F21: Tossal dels Tres Reis | G21: =IFERROR(INDEX('100 Cims FEEC'!$G$5:$G$526,MATCH(F21,'100 Cims FEEC'!$A$5:$A$526,0)),"No") | H21: =IFERROR(IF(INDEX('100 Cims FEEC'!$H$5:$H$526,MATCH(F21,'100 Cims FEEC'!$A$5:$A$526,0))="","",INDEX('100 Cims FEEC'!$H$5:$H$526,MATCH(F21,'100 Cims FEEC'!$A$5:$A$526,0))),"")
A22: Bages | B22: Sant Jeroni | C22: 1235.6 | D22: Montserrat | E22: Essencial | F22: Sant Jeroni | G22: =IFERROR(INDEX('100 Cims FEEC'!$G$5:$G$526,MATCH(F22,'100 Cims FEEC'!$A$5:$A$526,0)),"No") | H22: =IFERROR(IF(INDEX('100 Cims FEEC'!$H$5:$H$526,MATCH(F22,'100 Cims FEEC'!$A$5:$A$526,0))="","",INDEX('100 Cims FEEC'!$H$5:$H$526,MATCH(F22,'100 Cims FEEC'!$A$5:$A$526,0))),"")
A23: Anoia | B23: Sant Jeroni | C23: 1235.6 | D23: Montserrat | E23: Essencial | F23: Sant Jeroni | G23: =IFERROR(INDEX('100 Cims FEEC'!$G$5:$G$526,MATCH(F23,'100 Cims FEEC'!$A$5:$A$526,0)),"No") | H23: =IFERROR(IF(INDEX('100 Cims FEEC'!$H$5:$H$526,MATCH(F23,'100 Cims FEEC'!$A$5:$A$526,0))="","",INDEX('100 Cims FEEC'!$H$5:$H$526,MATCH(F23,'100 Cims FEEC'!$A$5:$A$526,0))),"")
A24: Terra Alta | B24: Tosseta Rasa | C24: 1216.7 | D24: Ports de Tortosa-Beseit | E24: No essencial | F24: Tosseta Rasa | G24: =IFERROR(INDEX('100 Cims FEEC'!$G$5:$G$526,MATCH(F24,'100 Cims FEEC'!$A$5:$A$526,0)),"No") | H24: =IFERROR(IF(INDEX('100 Cims FEEC'!$H$5:$H$526,MATCH(F24,'100 Cims FEEC'!$A$5:$A$526,0))="","",INDEX('100 Cims FEEC'!$H$5:$H$526,MATCH(F24,'100 Cims FEEC'!$A$5:$A$526,0))),"")
A25: Lluçanès | B25: Puigdon | C25: 1206 | E25: No
A26: Baix Camp | B26: Tossal de la Baltasana | C26: 1201.9 | D26: Muntanyes de Prades | E26: Essencial | F26: Tossal de la Baltasana | G26: =IFERROR(INDEX('100 Cims FEEC'!$G$5:$G$526,MATCH(F26,'100 Cims FEEC'!$A$5:$A$526,0)),"No") | H26: =IFERROR(IF(INDEX('100 Cims FEEC'!$H$5:$H$526,MATCH(F26,'100 Cims FEEC'!$A$5:$A$526,0))="","",INDEX('100 Cims FEEC'!$H$5:$H$526,MATCH(F26,'100 Cims FEEC'!$A$5:$A$526,0))),"")
A27: Conca de Barberà | B27: Tossal de la Baltasana | C27: 1201.9 | D27: Muntanyes de Prades | E27: Essencial | F27: Tossal de la Baltasana | G27: =IFERROR(INDEX('100 Cims FEEC'!$G$5:$G$526,MATCH(F27,'100 Cims FEEC'!$A$5:$A$526,0)),"No") | H27: =IFERROR(IF(INDEX('100 Cims FEEC'!$H$5:$H$526,MATCH(F27,'100 Cims FEEC'!$A$5:$A$526,0))="","",INDEX('100 Cims FEEC'!$H$5:$H$526,MATCH(F27,'100 Cims FEEC'!$A$5:$A$526,0))),"")
A28: Baix Llobregat | B28: L'Albarda Castellana | C28: 1177 | D28: Montserrat | E28: No essencial | F28: L’Albarda Castellana | G28: =IFERROR(INDEX('100 Cims FEEC'!$G$5:$G$526,MATCH(F28,'100 Cims FEEC'!$A$5:$A$526,0)),"No") | H28: =IFERROR(IF(INDEX('100 Cims FEEC'!$H$5:$H$526,MATCH(F28,'100 Cims FEEC'!$A$5:$A$526,0))="","",INDEX('100 Cims FEEC'!$H$5:$H$526,MATCH(F28,'100 Cims FEEC'!$A$5:$A$526,0))),"")
A29: Priorat | B29: Roca Corbatera | C29: 1162.8 | D29: Serra de Montsant | E29: Essencial | F29: Roca Corbatera | G29: =IFERROR(INDEX('100 Cims FEEC'!$G$5:$G$526,MATCH(F29,'100 Cims FEEC'!$A$5:$A$526,0)),"No") | H29: =IFERROR(IF(INDEX('100 Cims FEEC'!$H$5:$H$526,MATCH(F29,'100 Cims FEEC'!$A$5:$A$526,0))="","",INDEX('100 Cims FEEC'!$H$5:$H$526,MATCH(F29,'100 Cims FEEC'!$A$5:$A$526,0))),"")
A30: Vallès Occidental | B30: La Mola | C30: 1103.25 | D30: Serralada Prelitoral | E30: Essencial | F30: La Mola de Sant Llorenç del Munt | G30: =IFERROR(INDEX('100 Cims FEEC'!$G$5:$G$526,MATCH(F30,'100 Cims FEEC'!$A$5:$A$526,0)),"No") | H30: =IFERROR(IF(INDEX('100 Cims FEEC'!$H$5:$H$526,MATCH(F30,'100 Cims FEEC'!$A$5:$A$526,0))="","",INDEX('100 Cims FEEC'!$H$5:$H$526,MATCH(F30,'100 Cims FEEC'!$A$5:$A$526,0))),"")
A31: Moianès | B31: Serrat de Sant Joan | C31: 1065 | D31: Serralada Prelitoral | E31: No
A32: Garrigues | B32: La Cogulla | C32: 1022 | D32: Serra de la Llena | E32: No
A33: Alt Camp | B33: Punta de Barrina | C33: 1013.6 | D33: Muntanyes de Prades | E33: No
A34: Gironès | B34: Puigsou | C34: 991.3 | D34: Serralada Transversal | E34: No
A35: Ribera d'Ebre | B35: La Creu de Santos | C35: 941.9 | D35: Serra de Cardó | E35: Essencial | F35: Creu de Santos | G35: =IFERROR(INDEX('100 Cims FEEC'!$G$5:$G$526,MATCH(F35,'100 Cims FEEC'!$A$5:$A$526,0)),"No") | H35: =IFERROR(IF(INDEX('100 Cims FEEC'!$H$5:$H$526,MATCH(F35,'100 Cims FEEC'!$A$5:$A$526,0))="","",INDEX('100 Cims FEEC'!$H$5:$H$526,MATCH(F35,'100 Cims FEEC'!$A$5:$A$526,0))),"")
A36: Alt Penedès | B36: Puig de Solanes | C36: 914 | D36: Serralada prelitoral | E36: No
A37: Pla de l'Estany | B37: Comaestremer | C37: 885.8 | D37: Serra de Portelles | E37: No
A38: Baix Penedès | B38: Puig de la Talaia | C38: 861.3 | D38: Serra del Montmell | E38: No
A39: Segarra | B39: Serra de Montfred | C39: 833 | D39: Serra de Montfred (Depresió central) | E39: No
A40: Urgell | B40: Tossal Gros de Vallbona | C40: 802.9 | D40: Depressió central | E40: Essencial | F40: Tossal Gros de Vallbona | G40: =IFERROR(INDEX('100 Cims FEEC'!$G$5:$G$526,MATCH(F40,'100 Cims FEEC'!$A$5:$A$526,0)),"No") | H40: =IFERROR(IF(INDEX('100 Cims FEEC'!$H$5:$H$526,MATCH(F40,'100 Cims FEEC'!$A$5:$A$526,0))="","",INDEX('100 Cims FEEC'!$H$5:$H$526,MATCH(F40,'100 Cims FEEC'!$A$5:$A$526,0))),"")
A41: Maresme | B41: Turó d'en Vives | C41: 765.8 | D41: Massís del Montnegre | E41: No
...

Sheet Els meus punts
A1: Els meus punts
A2: Els teus punts, agrupats per carpeta, amb l'encreuament amb les llistes FEEC i de tresmils
A4: Grup (carpeta) | B4: Nom | C4: Altitud (m) | D4: Data | E4: Font altitud | F4: Cim FEEC | G4: Tipus FEEC | H4: Comarca FEEC | I4: Tresmil (llista 3000) | J4: Llista UIAA | K4: Tresmil català | L4: Latitud | M4: Longitud | N4: Mapa

Sheet Rutes
A1: Rutes i travesses
A2: Tracks del KMZ · distància i desnivell calculats a partir dels punts del track (filtre de soroll de 5 m)
A4: Ruta | B4: Etapa / track | C4: Any | D4: Data inici | E4: Distància (km) | F4: Desnivell + (m) | G4: Desnivell − (m) | H4: Alt. màx. (m) | I4: Alt. mín. (m) | J4: Durada (h) | K4: Inici (mapa)
